<?xml version="1.0" ?>
<robot name="sbot" xmlns:xacro="http://www.ros.org/wiki/xacro">

<xacro:include filename="$(find sbot_description)/urdf/materials.xacro" />
<xacro:include filename="$(find sbot_description)/urdf/sbot.trans" />
<xacro:include filename="$(find sbot_description)/gazebo/sbot_plugins.gazebo" />
<xacro:include filename="$(find sbot_description)/gazebo/sbot_materials.gazebo" />
<xacro:include filename="$(find sbot_description)/gazebo/sbot_physics.gazebo" />
<xacro:include filename="$(find realsense_ros_gazebo)/xacro/depthcam.xacro" />

<link name="base_link">
  <inertial>
    <origin rpy="0 0 0" xyz="0.0030130910059084394 0.0014669089311553155 0.055908150593734406"/>
    <mass value="0.23247786120094818"/>
    <inertia ixx="0.000458" ixy="0.0" ixz="1e-06" iyy="0.000499" iyz="1e-06" izz="0.000486"/>
  </inertial>
  <visual>
    <origin rpy="0 0 0" xyz="0 0 0"/>
    <geometry>
      <mesh filename="package://sbot_description/meshes/base_link.stl" scale="0.001 0.001 0.001"/>
    </geometry>
    <material name="silver"/>
  </visual>
  <collision>
    <origin rpy="0 0 0" xyz="0 0 0"/>
    <geometry>
      <mesh filename="package://sbot_description/meshes/base_link.stl" scale="0.001 0.001 0.001"/>
    </geometry>
  </collision>
</link>

<link name="motor_right_1">
  <inertial>
    <origin rpy="0 0 0" xyz="2.6693163065029304e-05 -0.031571062158037365 0.005505365676834351"/>
    <mass value="0.020403784271412942"/>
    <inertia ixx="2e-06" ixy="0.0" ixz="-0.0" iyy="0.0" iyz="-0.0" izz="2e-06"/>
  </inertial>
  <visual>
    <origin rpy="0 0 0" xyz="-0.002851 -0.001343 -0.016"/>
    <geometry>
      <mesh filename="package://sbot_description/meshes/motor_right_1.stl" scale="0.001 0.001 0.001"/>
    </geometry>
    <material name="silver"/>
  </visual>
  <collision>
    <origin rpy="0 0 0" xyz="-0.002851 -0.001343 -0.016"/>
    <geometry>
      <mesh filename="package://sbot_description/meshes/motor_right_1.stl" scale="0.001 0.001 0.001"/>
    </geometry>
  </collision>
</link>

<link name="motor_left_1">
  <inertial>
    <origin rpy="0 0 0" xyz="-2.7446533033708732e-05 0.03357062892676921 0.005505366569773813"/>
    <mass value="0.020403809268492824"/>
    <inertia ixx="2e-06" ixy="0.0" ixz="0.0" iyy="0.0" iyz="0.0" izz="2e-06"/>
  </inertial>
  <visual>
    <origin rpy="0 0 0" xyz="-0.002851 -0.001343 -0.016"/>
    <geometry>
      <mesh filename="package://sbot_description/meshes/motor_left_1.stl" scale="0.001 0.001 0.001"/>
    </geometry>
    <material name="silver"/>
  </visual>
  <collision>
    <origin rpy="0 0 0" xyz="-0.002851 -0.001343 -0.016"/>
    <geometry>
      <mesh filename="package://sbot_description/meshes/motor_left_1.stl" scale="0.001 0.001 0.001"/>
    </geometry>
  </collision>
</link>

<link name="wheel_right_1">
  <inertial>
    <origin rpy="0 0 0" xyz="-3.7664430868134327e-07 0.0075395273198648055 -6.141588042178625e-06"/>
    <mass value="0.020021601354988452"/>
    <inertia ixx="3e-06" ixy="0.0" ixz="0.0" iyy="5e-06" iyz="-0.0" izz="3e-06"/>
  </inertial>
  <visual>
    <origin rpy="0 0 0" xyz="-0.002851 0.056957 -0.021"/>
    <geometry>
      <mesh filename="package://sbot_description/meshes/wheel_right_1.stl" scale="0.001 0.001 0.001"/>
    </geometry>
    <material name="silver"/>
  </visual>
  <collision>
    <origin rpy="0 0 0" xyz="-0.002851 0.056957 -0.021"/>
    <geometry>
      <mesh filename="package://sbot_description/meshes/wheel_right_1.stl" scale="0.001 0.001 0.001"/>
    </geometry>
  </collision>
</link>

<link name="wheel_left_1">
  <inertial>
    <origin rpy="0 0 0" xyz="-3.7812528066397816e-07 -0.007539957792592984 -6.14158804220985e-06"/>
    <mass value="0.02002160135498825"/>
    <inertia ixx="3e-06" ixy="0.0" ixz="0.0" iyy="5e-06" iyz="0.0" izz="3e-06"/>
  </inertial>
  <visual>
    <origin rpy="0 0 0" xyz="-0.002851 -0.061643 -0.021"/>
    <geometry>
      <mesh filename="package://sbot_description/meshes/wheel_left_1.stl" scale="0.001 0.001 0.001"/>
    </geometry>
    <material name="silver"/>
  </visual>
  <collision>
    <origin rpy="0 0 0" xyz="-0.002851 -0.061643 -0.021"/>
    <geometry>
      <mesh filename="package://sbot_description/meshes/wheel_left_1.stl" scale="0.001 0.001 0.001"/>
    </geometry>
  </collision>
</link>

<link name="raspberry_pi_1">
  <inertial>
    <origin rpy="0 0 0" xyz="-0.0012543861563304364 -0.01496568809013773 0.004888830680915349"/>
    <mass value="0.13472167579144456"/>
    <inertia ixx="8.3e-05" ixy="0.0" ixz="0.0" iyy="4.1e-05" iyz="9e-06" izz="0.000118"/>
  </inertial>
  <visual>
    <origin rpy="0 0 0" xyz="-0.002851 -0.001343 -0.056"/>
    <geometry>
      <mesh filename="package://sbot_description/meshes/raspberry_pi_1.stl" scale="0.001 0.001 0.001"/>
    </geometry>
    <material name="silver"/>
  </visual>
  <collision>
    <origin rpy="0 0 0" xyz="-0.002851 -0.001343 -0.056"/>
    <geometry>
      <mesh filename="package://sbot_description/meshes/raspberry_pi_1.stl" scale="0.001 0.001 0.001"/>
    </geometry>
  </collision>
</link>

<link name="lidar_1">
  <inertial>
    <origin rpy="0 0 0" xyz="-0.0002944773615637473 -0.0010002155704046025 0.037701142222791195"/>
    <mass value="1.151561654231423"/>
    <inertia ixx="0.000489" ixy="0.0" ixz="-0.000148" iyy="0.000861" iyz="0.0" izz="0.000987"/>
  </inertial>
  <visual>
    <origin rpy="0 0 0" xyz="-0.002851 -0.001343 -0.096"/>
    <geometry>
      <mesh filename="package://sbot_description/meshes/lidar_1.stl" scale="0.001 0.001 0.001"/>
    </geometry>
    <material name="silver"/>
  </visual>
  <collision>
    <origin rpy="0 0 0" xyz="-0.002851 -0.001343 -0.096"/>
    <geometry>
      <mesh filename="package://sbot_description/meshes/lidar_1.stl" scale="0.001 0.001 0.001"/>
    </geometry>
  </collision>
</link>

<link name="motor_driver_1">
  <inertial>
    <origin rpy="0 0 0" xyz="-0.04002253095513978 -0.0003531151179055718 0.006585464632791877"/>
    <mass value="0.009766883957531803"/>
    <inertia ixx="2e-06" ixy="0.0" ixz="0.0" iyy="2e-06" iyz="0.0" izz="3e-06"/>
  </inertial>
  <visual>
    <origin rpy="0 0 0" xyz="-0.002851 -0.001343 -0.016"/>
    <geometry>
      <mesh filename="package://sbot_description/meshes/motor_driver_1.stl" scale="0.001 0.001 0.001"/>
    </geometry>
    <material name="silver"/>
  </visual>
  <collision>
    <origin rpy="0 0 0" xyz="-0.002851 -0.001343 -0.016"/>
    <geometry>
      <mesh filename="package://sbot_description/meshes/motor_driver_1.stl" scale="0.001 0.001 0.001"/>
    </geometry>
  </collision>
</link>

<link name="imu_1">
  <inertial>
    <origin rpy="0 0 0" xyz="-3.7779124422094093e-07 -2.1557040461332375e-07 -0.0029999999999997806"/>
    <mass value="0.01098999999999996"/>
    <inertia ixx="1e-06" ixy="-0.0" ixz="0.0" iyy="0.0" iyz="-0.0" izz="1e-06"/>
  </inertial>
  <visual>
    <origin rpy="0 0 0" xyz="-0.002851 -0.001343 -0.091"/>
    <geometry>
      <mesh filename="package://sbot_description/meshes/imu_1.stl" scale="0.001 0.001 0.001"/>
    </geometry>
    <material name="silver"/>
  </visual>
  <collision>
    <origin rpy="0 0 0" xyz="-0.002851 -0.001343 -0.091"/>
    <geometry>
      <mesh filename="package://sbot_description/meshes/imu_1.stl" scale="0.001 0.001 0.001"/>
    </geometry>
  </collision>
</link>

<link name="caster_front_1">
  <inertial>
    <origin rpy="0 0 0" xyz="0.04499962220875584 -2.155704046666665e-07 -0.004333823529411766"/>
    <mass value="0.004055599766243573"/>
    <inertia ixx="0.0" ixy="-0.0" ixz="-0.0" iyy="0.0" iyz="0.0" izz="0.0"/>
  </inertial>
  <visual>
    <origin rpy="0 0 0" xyz="-0.002851 -0.001343 -0.011"/>
    <geometry>
      <mesh filename="package://sbot_description/meshes/caster_front_1.stl" scale="0.001 0.001 0.001"/>
    </geometry>
    <material name="silver"/>
  </visual>
  <collision>
    <origin rpy="0 0 0" xyz="-0.002851 -0.001343 -0.011"/>
    <geometry>
      <mesh filename="package://sbot_description/meshes/caster_front_1.stl" scale="0.001 0.001 0.001"/>
    </geometry>
  </collision>
</link>

<link name="caster_back_1">
  <inertial>
    <origin rpy="0 0 0" xyz="-0.045000377791244155 -2.1557040466796754e-07 -0.004333823529411766"/>
    <mass value="0.004055599766243573"/>
    <inertia ixx="0.0" ixy="-0.0" ixz="0.0" iyy="0.0" iyz="-0.0" izz="0.0"/>
  </inertial>
  <visual>
    <origin rpy="0 0 0" xyz="-0.002851 -0.001343 -0.011"/>
    <geometry>
      <mesh filename="package://sbot_description/meshes/caster_back_1.stl" scale="0.001 0.001 0.001"/>
    </geometry>
    <material name="silver"/>
  </visual>
  <collision>
    <origin rpy="0 0 0" xyz="-0.002851 -0.001343 -0.011"/>
    <geometry>
      <mesh filename="package://sbot_description/meshes/caster_back_1.stl" scale="0.001 0.001 0.001"/>
    </geometry>
  </collision>
</link>

<link name="realsense_camera_1">
  <inertial>
    <origin rpy="0 0 0" xyz="0.04694505772227793 -0.0002201936226193231 -0.01593916944571505"/>
    <mass value="0.3515134579013281"/>
    <inertia ixx="0.000227" ixy="1e-06" ixz="0.0" iyy="3.2e-05" iyz="-0.0" izz="0.000229"/>
  </inertial>
  <visual>
    <origin rpy="0 0 0" xyz="-0.012851 -0.001343 -0.091"/>
    <geometry>
      <mesh filename="package://sbot_description/meshes/realsense_camera_1.stl" scale="0.001 0.001 0.001"/>
    </geometry>
    <material name="silver"/>
  </visual>
  <collision>
    <origin rpy="0 0 0" xyz="-0.012851 -0.001343 -0.091"/>
    <geometry>
      <mesh filename="package://sbot_description/meshes/realsense_camera_1.stl" scale="0.001 0.001 0.001"/>
    </geometry>
  </collision>
</link>

<joint name="right_motor_joint" type="fixed">
  <origin rpy="0 0 0" xyz="0.002851 0.001343 0.016"/>
  <parent link="base_link"/>
  <child link="motor_right_1"/>
</joint>

<joint name="left_motor_joint" type="fixed">
  <origin rpy="0 0 0" xyz="0.002851 0.001343 0.016"/>
  <parent link="base_link"/>
  <child link="motor_left_1"/>
</joint>

<joint name="right_wheel_joint" type="continuous">
  <origin rpy="0 0 0" xyz="0.0 -0.0583 0.005"/>
  <parent link="motor_right_1"/>
  <child link="wheel_right_1"/>
  <axis xyz="-0.0 1.0 -0.0"/>
</joint>

<joint name="left_wheel_joint" type="continuous">
  <origin rpy="0 0 0" xyz="0.0 0.0603 0.005"/>
  <parent link="motor_left_1"/>
  <child link="wheel_left_1"/>
  <axis xyz="-0.0 1.0 -0.0"/>
</joint>

<joint name="r_pi_joint" type="fixed">
  <origin rpy="0 0 0" xyz="0.002851 0.001343 0.056"/>
  <parent link="base_link"/>
  <child link="raspberry_pi_1"/>
</joint>

<joint name="lidar_joint" type="fixed">
  <origin rpy="0 0 0" xyz="0.002851 0.001343 0.096"/>
  <parent link="base_link"/>
  <child link="lidar_1"/>
</joint>

<joint name="Rigid84" type="fixed">
  <origin rpy="0 0 0" xyz="0.002851 0.001343 0.016"/>
  <parent link="base_link"/>
  <child link="motor_driver_1"/>
</joint>

<joint name="Rigid85" type="fixed">
  <origin rpy="0 0 0" xyz="0.002851 0.001343 0.091"/>
  <parent link="base_link"/>
  <child link="imu_1"/>
</joint>

<joint name="front_caster_joint" type="fixed">
  <origin rpy="0 0 0" xyz="0.002851 0.001343 0.011"/>
  <parent link="base_link"/>
  <child link="caster_front_1"/>
</joint>

<joint name="back_caster_joint" type="fixed">
  <origin rpy="0 0 0" xyz="0.002851 0.001343 0.011"/>
  <parent link="base_link"/>
  <child link="caster_back_1"/>
</joint>

<joint name="Rigid88" type="fixed">
  <origin rpy="0 0 0" xyz="0.01 0.0 0.0"/>
  <parent link="imu_1"/>
  <child link="realsense_camera_1"/>
</joint>

</robot>
